Workbook

Sheet Summary
A1: PROJECT DARWIN — Datacube Summary
A2: Currency: £ GBP — Source: GMSL_Revenue_Lines_Clip.xlsx (5 Apr 2026) — All FY actuals
A4: Key metric | B4: FY2014A | C4: FY2015A | D4: FY2016A | E4: FY2017A | F4: FY2018A | G4: FY2019A | H4: FY2020A | I4: FY2021A | J4: FY2022A | K4: FY2023A | L4: FY2024A | M4: FY2025A | N4: FY2026A
A5: Total revenue (£) | B5: ='Revenue Overview'!B4 | C5: ='Revenue Overview'!C4 | D5: ='Revenue Overview'!D4 | E5: ='Revenue Overview'!E4 | F5: ='Revenue Overview'!F4 | G5: ='Revenue Overview'!G4 | H5: ='Revenue Overview'!H4 | I5: ='Revenue Overview'!I4 | ... N5: ='Revenue Overview'!N4
A6: YoY growth | B6: ='Revenue Overview'!B5 | C6: ='Revenue Overview'!C5 | D6: ='Revenue Overview'!D5 | E6: ='Revenue Overview'!E5 | F6: ='Revenue Overview'!F5 | G6: ='Revenue Overview'!G5 | H6: ='Revenue Overview'!H5 | I6: ='Revenue Overview'!I5 | ... N6: ='Revenue Overview'!N5
A7: Indexed (FY14 = 100) | B7: ='Revenue Overview'!B6 | C7: ='Revenue Overview'!C6 | D7: ='Revenue Overview'!D6 | E7: ='Revenue Overview'!E6 | F7: ='Revenue Overview'!F6 | G7: ='Revenue Overview'!G6 | H7: ='Revenue Overview'!H6 | I7: ='Revenue Overview'!I6 | ... N7: ='Revenue Overview'!N6
A9: Software vs Services
A10: Software revenue (£) | B10: ='Software vs Services'!B5 | C10: ='Software vs Services'!C5 | D10: ='Software vs Services'!D5 | E10: ='Software vs Services'!E5 | F10: ='Software vs Services'!F5 | G10: ='Software vs Services'!G5 | H10: ='Software vs Services'!H5 | I10: ='Software vs Services'!I5 | ... N10: ='Software vs Services'!N5
A11: Services revenue (£) | B11: ='Software vs Services'!B6 | C11: ='Software vs Services'!C6 | D11: ='Software vs Services'!D6 | E11: ='Software vs Services'!E6 | F11: ='Software vs Services'!F6 | G11: ='Software vs Services'!G6 | H11: ='Software vs Services'!H6 | I11: ='Software vs Services'!I6 | ... N11: ='Software vs Services'!N6
A12: Software % of total | B12: ='Software vs Services'!B9 | C12: ='Software vs Services'!C9 | D12: ='Software vs Services'!D9 | E12: ='Software vs Services'!E9 | F12: ='Software vs Services'!F9 | G12: ='Software vs Services'!G9 | H12: ='Software vs Services'!H9 | I12: ='Software vs Services'!I9 | ... N12: ='Software vs Services'!N9
A13: Software YoY growth | B13: ='Software vs Services'!B12 | C13: ='Software vs Services'!C12 | D13: ='Software vs Services'!D12 | E13: ='Software vs Services'!E12 | F13: ='Software vs Services'!F12 | G13: ='Software vs Services'!G12 | H13: ='Software vs Services'!H12 | I13: ='Software vs Services'!I12 | ... N13: ='Software vs Services'!N12
A14: Services YoY growth | B14: ='Software vs Services'!B13 | C14: ='Software vs Services'!C13 | D14: ='Software vs Services'!D13 | E14: ='Software vs Services'!E13 | F14: ='Software vs Services'!F13 | G14: ='Software vs Services'!G13 | H14: ='Software vs Services'!H13 | I14: ='Software vs Services'!I13 | ... N14: ='Software vs Services'!N13
A16: Client base
A17: # Active clients | B17: ='Client Dynamics'!B5 | C17: ='Client Dynamics'!C5 | D17: ='Client Dynamics'!D5 | E17: ='Client Dynamics'!E5 | F17: ='Client Dynamics'!F5 | G17: ='Client Dynamics'!G5 | H17: ='Client Dynamics'!H5 | I17: ='Client Dynamics'!I5 | ... N17: ='Client Dynamics'!N5
A18: # New clients | B18: ='Client Dynamics'!B6 | C18: ='Client Dynamics'!C6 | D18: ='Client Dynamics'!D6 | E18: ='Client Dynamics'!E6 | F18: ='Client Dynamics'!F6 | G18: ='Client Dynamics'!G6 | H18: ='Client Dynamics'!H6 | I18: ='Client Dynamics'!I6 | ... N18: ='Client Dynamics'!N6
A19: # Churned clients | B19: ='Client Dynamics'!B7 | C19: ='Client Dynamics'!C7 | D19: ='Client Dynamics'!D7 | E19: ='Client Dynamics'!E7 | F19: ='Client Dynamics'!F7 | G19: ='Client Dynamics'!G7 | H19: ='Client Dynamics'!H7 | I19: ='Client Dynamics'!I7 | ... N19: ='Client Dynamics'!N7
A20: Logo retention % | B20: ='Client Dynamics'!B10 | C20: ='Client Dynamics'!C10 | D20: ='Client Dynamics'!D10 | E20: ='Client Dynamics'!E10 | F20: ='Client Dynamics'!F10 | G20: ='Client Dynamics'!G10 | H20: ='Client Dynamics'!H10 | I20: ='Client Dynamics'!I10 | ... N20: ='Client Dynamics'!N10
A21: GRR — same client base | B21: ='Client Dynamics'!B11 | C21: ='Client Dynamics'!C11 | D21: ='Client Dynamics'!D11 | E21: ='Client Dynamics'!E11 | F21: ='Client Dynamics'!F11 | G21: ='Client Dynamics'!G11 | H21: ='Client Dynamics'!H11 | I21: ='Client Dynamics'!I11 | ... N21: ='Client Dynamics'!N11
A22: NRR — w/ expansion | B22: ='Client Dynamics'!B12 | C22: ='Client Dynamics'!C12 | D22: ='Client Dynamics'!D12 | E22: ='Client Dynamics'!E12 | F22: ='Client Dynamics'!F12 | G22: ='Client Dynamics'!G12 | H22: ='Client Dynamics'!H12 | I22: ='Client Dynamics'!I12 | ... N22: ='Client Dynamics'!N12
A23: ARPC (£) | B23: ='Client Dynamics'!B14 | C23: ='Client Dynamics'!C14 | D23: ='Client Dynamics'!D14 | E23: ='Client Dynamics'!E14 | F23: ='Client Dynamics'!F14 | G23: ='Client Dynamics'!G14 | H23: ='Client Dynamics'!H14 | I23: ='Client Dynamics'!I14 | ... N23: ='Client Dynamics'!N14
A25: Concentration
A26: Top 1 client share | B26: ='Client Concentration'!B5 | C26: ='Client Concentration'!C5 | D26: ='Client Concentration'!D5 | E26: ='Client Concentration'!E5 | F26: ='Client Concentration'!F5 | G26: ='Client Concentration'!G5 | H26: ='Client Concentration'!H5 | I26: ='Client Concentration'!I5 | ... N26: ='Client Concentration'!N5
A27: Top 5 client share | B27: ='Client Concentration'!B6 | C27: ='Client Concentration'!C6 | D27: ='Client Concentration'!D6 | E27: ='Client Concentration'!E6 | F27: ='Client Concentration'!F6 | G27: ='Client Concentration'!G6 | H27: ='Client Concentration'!H6 | I27: ='Client Concentration'!I6 | ... N27: ='Client Concentration'!N6
A28: Top 10 client share | B28: ='Client Concentration'!B7 | C28: ='Client Concentration'!C7 | D28: ='Client Concentration'!D7 | E28: ='Client Concentration'!E7 | F28: ='Client Concentration'!F7 | G28: ='Client Concentration'!G7 | H28: ='Client Concentration'!H7 | I28: ='Client Concentration'!I7 | ... N28: ='Client Concentration'!N7
A29: Top 20 client share | B29: ='Client Concentration'!B8 | C29: ='Client Concentration'!C8 | D29: ='Client Concentration'!D8 | E29: ='Client Concentration'!E8 | F29: ='Client Concentration'!F8 | G29: ='Client Concentration'!G8 | H29: ='Client Concentration'!H8 | I29: ='Client Concentration'!I8 | ... N29: ='Client Concentration'!N8

Sheet Revenue Overview
A1: Revenue Overview — Project Darwin (£ GBP)
A3: Metric | B3: FY2014A | C3: FY2015A | D3: FY2016A | E3: FY2017A | F3: FY2018A | G3: FY2019A | H3: FY2020A | I3: FY2021A | J3: FY2022A | K3: FY2023A | L3: FY2024A | M3: FY2025A | N3: FY2026A | O3: CAGR FY14-FY23 | P3: CAGR FY14-FY26
A4: Total revenue (£) | B4: =SUM(Source_Evolution!$E$3:$E$731) | C4: =SUM(Source_Evolution!$F$3:$F$731) | D4: =SUM(Source_Evolution!$G$3:$G$731) | E4: =SUM(Source_Evolution!$H$3:$H$731) | F4: =SUM(Source_Evolution!$I$3:$I$731) | G4: =SUM(Source_Evolution!$J$3:$J$731) | H4: =SUM(Source_Evolution!$K$3:$K$731) | I4: =SUM(Source_Evolution!$L$3:$L$731) | J4: =SUM(Source_Evolution!$M$3:$M$731) | K4: =SUM(Source_Evolution!$N$3:$N$731) | L4: =SUM(Source_Evolution!$O$3:$O$731) | M4: =SUM(Source_Evolution!$P$3:$P$731) | N4: =SUM(Source_Evolution!$Q$3:$Q$731) | O4: =IFERROR((J4/B4)^(1/9)-1,"-") | P4: =IFERROR((N4/B4)^(1/12)-1,"-")
A5: YoY growth % | B5: - | C5: =IFERROR(C4/B4-1,"-") | D5: =IFERROR(D4/C4-1,"-") | E5: =IFERROR(E4/D4-1,"-") | F5: =IFERROR(F4/E4-1,"-") | G5: =IFERROR(G4/F4-1,"-") | H5: =IFERROR(H4/G4-1,"-") | I5: =IFERROR(I4/H4-1,"-") | J5: =IFERROR(J4/I4-1,"-") | ... N5: =IFERROR(N4/M4-1,"-")
A6: Indexed (FY14 = 100) | B6: =IFERROR(B4/$B$4*100,"-") | C6: =IFERROR(C4/$B$4*100,"-") | D6: =IFERROR(D4/$B$4*100,"-") | E6: =IFERROR(E4/$B$4*100,"-") | F6: =IFERROR(F4/$B$4*100,"-") | G6: =IFERROR(G4/$B$4*100,"-") | H6: =IFERROR(H4/$B$4*100,"-") | I6: =IFERROR(I4/$B$4*100,"-") | ... N6: =IFERROR(N4/$B$4*100,"-")
A8: # Active revenue lines | B8: =COUNTIFS(Source_Evolution!$E$3:$E$731,">0") | C8: =COUNTIFS(Source_Evolution!$F$3:$F$731,">0") | D8: =COUNTIFS(Source_Evolution!$G$3:$G$731,">0") | E8: =COUNTIFS(Source_Evolution!$H$3:$H$731,">0") | F8: =COUNTIFS(Source_Evolution!$I$3:$I$731,">0") | G8: =COUNTIFS(Source_Evolution!$J$3:$J$731,">0") | H8: =COUNTIFS(Source_Evolution!$K$3:$K$731,">0") | I8: =COUNTIFS(Source_Evolution!$L$3:$L$731,">0") | J8: =COUNTIFS(Source_Evolution!$M$3:$M$731,">0") | K8: =COUNTIFS(Source_Evolution!$N$3:$N$731,">0") | L8: =COUNTIFS(Source_Evolution!$O$3:$O$731,">0") | M8: =COUNTIFS(Source_Evolution!$P$3:$P$731,">0") | N8: =COUNTIFS(Source_Evolution!$Q$3:$Q$731,">0")

Sheet Software vs Services
A1: Software vs Services — Revenue split (£ GBP)
A2: Software = Dept "Software". Services = Dept "Operations" + "CVA" + "Power".
A4: Metric | B4: FY2014A | C4: FY2015A | D4: FY2016A | E4: FY2017A | F4: FY2018A | G4: FY2019A | H4: FY2020A | I4: FY2021A | J4: FY2022A | K4: FY2023A | L4: FY2024A | M4: FY2025A | N4: FY2026A | O4: CAGR FY14-FY26
A5: Software revenue (£) | B5: =SUMIFS(Source_Evolution!$E$3:$E$731,Source_Evolution!$B$3:$B$731,"Software") | C5: =SUMIFS(Source_Evolution!$F$3:$F$731,Source_Evolution!$B$3:$B$731,"Software") | D5: =SUMIFS(Source_Evolution!$G$3:$G$731,Source_Evolution!$B$3:$B$731,"Software") | E5: =SUMIFS(Source_Evolution!$H$3:$H$731,Source_Evolution!$B$3:$B$731,"Software") | F5: =SUMIFS(Source_Evolution!$I$3:$I$731,Source_Evolution!$B$3:$B$731,"Software") | G5: =SUMIFS(Source_Evolution!$J$3:$J$731,Source_Evolution!$B$3:$B$731,"Software") | H5: =SUMIFS(Source_Evolution!$K$3:$K$731,Source_Evolution!$B$3:$B$731,"Software") | I5: =SUMIFS(Source_Evolution!$L$3:$L$731,Source_Evolution!$B$3:$B$731,"Software") | J5: =SUMIFS(Source_Evolution!$M$3:$M$731,Source_Evolution!$B$3:$B$731,"Software") | K5: =SUMIFS(Source_Evolution!$N$3:$N$731,Source_Evolution!$B$3:$B$731,"Software") | L5: =SUMIFS(Source_Evolution!$O$3:$O$731,Source_Evolution!$B$3:$B$731,"Software") | M5: =SUMIFS(Source_Evolution!$P$3:$P$731,Source_Evolution!$B$3:$B$731,"Software") | N5: =SUMIFS(Source_Evolution!$Q$3:$Q$731,Source_Evolution!$B$3:$B$731,"Software") | O5: =IFERROR((N5/B5)^(1/12)-1,"-")
A6: Services revenue (£) | B6: =SUMIFS(Source_Evolution!$E$3:$E$731,Source_Evolution!$B$3:$B$731,"Operations")+SUMIFS(Source_Evolution!$E$3:$E$731,Source_Evolution!$B$3:$B$731,"CVA")+SUMIFS(Source_Evolution!$E$3:$E$731,Source_Evolution!$B$3:$B$731,"Power") | C6: =SUMIFS(Source_Evolution!$F$3:$F$731,Source_Evolution!$B$3:$B$731,"Operations")+SUMIFS(Source_Evolution!$F$3:$F$731,Source_Evolution!$B$3:$B$731,"CVA")+SUMIFS(Source_Evolution!$F$3:$F$731,Source_Evolution!$B$3:$B$731,"Power") | D6: =SUMIFS(Source_Evolution!$G$3:$G$731,Source_Evolution!$B$3:$B$731,"Operations")+SUMIFS(Source_Evolution!$G$3:$G$731,Source_Evolution!$B$3:$B$731,"CVA")+SUMIFS(Source_Evolution!$G$3:$G$731,Source_Evolution!$B$3:$B$731,"Power") | E6: =SUMIFS(Source_Evolution!$H$3:$H$731,Source_Evolution!$B$3:$B$731,"Operations")+SUMIFS(Source_Evolution!$H$3:$H$731,Source_Evolution!$B$3:$B$731,"CVA")+SUMIFS(Source_Evolution!$H$3:$H$731,Source_Evolution!$B$3:$B$731,"Power") | F6: =SUMIFS(Source_Evolution!$I$3:$I$731,Source_Evolution!$B$3:$B$731,"Operations")+SUMIFS(Source_Evolution!$I$3:$I$731,Source_Evolution!$B$3:$B$731,"CVA")+SUMIFS(Source_Evolution!$I$3:$I$731,Source_Evolution!$B$3:$B$731,"Power") | G6: =SUMIFS(Source_Evolution!$J$3:$J$731,Source_Evolution!$B$3:$B$731,"Operations")+SUMIFS(Source_Evolution!$J$3:$J$731,Source_Evolution!$B$3:$B$731,"CVA")+SUMIFS(Source_Evolution!$J$3:$J$731,Source_Evolution!$B$3:$B$731,"Power") | H6: =SUMIFS(Source_Evolution!$K$3:$K$731,Source_Evolution!$B$3:$B$731,"Operations")+SUMIFS(Source_Evolution!$K$3:$K$731,Source_Evolution!$B$3:$B$731,"CVA")+SUMIFS(Source_Evolution!$K$3:$K$731,Source_Evolution!$B$3:$B$731,"Power") | I6: =SUMIFS(Source_Evolution!$L$3:$L$731,Source_Evolution!$B$3:$B$731,"Operations")+SUMIFS(Source_Evolution!$L$3:$L$731,Source_Evolution!$B$3:$B$731,"CVA")+SUMIFS(Source_Evolution!$L$3:$L$731,Source_Evolution!$B$3:$B$731,"Power") | J6: =SUMIFS(Source_Evolution!$M$3:$M$731,Source_Evolution!$B$3:$B$731,"Operations")+SUMIFS(Source_Evolution!$M$3:$M$731,Source_Evolution!$B$3:$B$731,"CVA")+SUMIFS(Source_Evolution!$M$3:$M$731,Source_Evolution!$B$3:$B$731,"Power") | K6: =SUMIFS(Source_Evolution!$N$3:$N$731,Source_Evolution!$B$3:$B$731,"Operations")+SUMIFS(Source_Evolution!$N$3:$N$731,Source_Evolution!$B$3:$B$731,"CVA")+SUMIFS(Source_Evolution!$N$3:$N$731,Source_Evolution!$B$3:$B$731,"Power") | L6: =SUMIFS(Source_Evolution!$O$3:$O$731,Source_Evolution!$B$3:$B$731,"Operations")+SUMIFS(Source_Evolution!$O$3:$O$731,Source_Evolution!$B$3:$B$731,"CVA")+SUMIFS(Source_Evolution!$O$3:$O$731,Source_Evolution!$B$3:$B$731,"Power") | M6: =SUMIFS(Source_Evolution!$P$3:$P$731,Source_Evolution!$B$3:$B$731,"Operations")+SUMIFS(Source_Evolution!$P$3:$P$731,Source_Evolution!$B$3:$B$731,"CVA")+SUMIFS(Source_Evolution!$P$3:$P$731,Source_Evolution!$B$3:$B$731,"Power") | N6: =SUMIFS(Source_Evolution!$Q$3:$Q$731,Source_Evolution!$B$3:$B$731,"Operations")+SUMIFS(Source_Evolution!$Q$3:$Q$731,Source_Evolution!$B$3:$B$731,"CVA")+SUMIFS(Source_Evolution!$Q$3:$Q$731,Source_Evolution!$B$3:$B$731,"Power") | O6: =IFERROR((N6/B6)^(1/12)-1,"-")
A7: Total revenue (£) | B7: =B5+B6 | C7: =C5+C6 | D7: =D5+D6 | E7: =E5+E6 | F7: =F5+F6 | G7: =G5+G6 | H7: =H5+H6 | I7: =I5+I6 | ... N7: =N5+N6 | O7: =IFERROR((N7/B7)^(1/12)-1,"-")
A9: Software % of total | B9: =IFERROR(B5/B7,"-") | C9: =IFERROR(C5/C7,"-") | D9: =IFERROR(D5/D7,"-") | E9: =IFERROR(E5/E7,"-") | F9: =IFERROR(F5/F7,"-") | G9: =IFERROR(G5/G7,"-") | H9: =IFERROR(H5/H7,"-") | I9: =IFERROR(I5/I7,"-") | ... N9: =IFERROR(N5/N7,"-")
A10: Services % of total | B10: =IFERROR(B6/B7,"-") | C10: =IFERROR(C6/C7,"-") | D10: =IFERROR(D6/D7,"-") | E10: =IFERROR(E6/E7,"-") | F10: =IFERROR(F6/F7,"-") | G10: =IFERROR(G6/G7,"-") | H10: =IFERROR(H6/H7,"-") | I10: =IFERROR(I6/I7,"-") | ... N10: =IFERROR(N6/N7,"-")
A12: Software YoY growth | B12: - | C12: =IFERROR(C5/B5-1,"-") | D12: =IFERROR(D5/C5-1,"-") | E12: =IFERROR(E5/D5-1,"-") | F12: =IFERROR(F5/E5-1,"-") | G12: =IFERROR(G5/F5-1,"-") | H12: =IFERROR(H5/G5-1,"-") | I12: =IFERROR(I5/H5-1,"-") | J12: =IFERROR(J5/I5-1,"-") | ... N12: =IFERROR(N5/M5-1,"-")
A13: Services YoY growth | B13: - | C13: =IFERROR(C6/B6-1,"-") | D13: =IFERROR(D6/C6-1,"-") | E13: =IFERROR(E6/D6-1,"-") | F13: =IFERROR(F6/E6-1,"-") | G13: =IFERROR(G6/F6-1,"-") | H13: =IFERROR(H6/G6-1,"-") | I13: =IFERROR(I6/H6-1,"-") | J13: =IFERROR(J6/I6-1,"-") | ... N13: =IFERROR(N6/M6-1,"-")
A15: # Software revenue lines | B15: =COUNTIFS(Source_Evolution!$B$3:$B$731,"Software",Source_Evolution!$E$3:$E$731,">0") | C15: =COUNTIFS(Source_Evolution!$B$3:$B$731,"Software",Source_Evolution!$F$3:$F$731,">0") | D15: =COUNTIFS(Source_Evolution!$B$3:$B$731,"Software",Source_Evolution!$G$3:$G$731,">0") | E15: =COUNTIFS(Source_Evolution!$B$3:$B$731,"Software",Source_Evolution!$H$3:$H$731,">0") | F15: =COUNTIFS(Source_Evolution!$B$3:$B$731,"Software",Source_Evolution!$I$3:$I$731,">0") | G15: =COUNTIFS(Source_Evolution!$B$3:$B$731,"Software",Source_Evolution!$J$3:$J$731,">0") | H15: =COUNTIFS(Source_Evolution!$B$3:$B$731,"Software",Source_Evolution!$K$3:$K$731,">0") | I15: =COUNTIFS(Source_Evolution!$B$3:$B$731,"Software",Source_Evolution!$L$3:$L$731,">0") | J15: =COUNTIFS(Source_Evolution!$B$3:$B$731,"Software",Source_Evolution!$M$3:$M$731,">0") | K15: =COUNTIFS(Source_Evolution!$B$3:$B$731,"Software",Source_Evolution!$N$3:$N$731,">0") | L15: =COUNTIFS(Source_Evolution!$B$3:$B$731,"Software",Source_Evolution!$O$3:$O$731,">0") | M15: =COUNTIFS(Source_Evolution!$B$3:$B$731,"Software",Source_Evolution!$P$3:$P$731,">0") | N15: =COUNTIFS(Source_Evolution!$B$3:$B$731,"Software",Source_Evolution!$Q$3:$Q$731,">0")
A16: # Services revenue lines | B16: =COUNTIFS(Source_Evolution!$B$3:$B$731,"<>Software",Source_Evolution!$E$3:$E$731,">0") | C16: =COUNTIFS(Source_Evolution!$B$3:$B$731,"<>Software",Source_Evolution!$F$3:$F$731,">0") | D16: =COUNTIFS(Source_Evolution!$B$3:$B$731,"<>Software",Source_Evolution!$G$3:$G$731,">0") | E16: =COUNTIFS(Source_Evolution!$B$3:$B$731,"<>Software",Source_Evolution!$H$3:$H$731,">0") | F16: =COUNTIFS(Source_Evolution!$B$3:$B$731,"<>Software",Source_Evolution!$I$3:$I$731,">0") | G16: =COUNTIFS(Source_Evolution!$B$3:$B$731,"<>Software",Source_Evolution!$J$3:$J$731,">0") | H16: =COUNTIFS(Source_Evolution!$B$3:$B$731,"<>Software",Source_Evolution!$K$3:$K$731,">0") | I16: =COUNTIFS(Source_Evolution!$B$3:$B$731,"<>Software",Source_Evolution!$L$3:$L$731,">0") | J16: =COUNTIFS(Source_Evolution!$B$3:$B$731,"<>Software",Source_Evolution!$M$3:$M$731,">0") | K16: =COUNTIFS(Source_Evolution!$B$3:$B$731,"<>Software",Source_Evolution!$N$3:$N$731,">0") | L16: =COUNTIFS(Source_Evolution!$B$3:$B$731,"<>Software",Source_Evolution!$O$3:$O$731,">0") | M16: =COUNTIFS(Source_Evolution!$B$3:$B$731,"<>Software",Source_Evolution!$P$3:$P$731,">0") | N16: =COUNTIFS(Source_Evolution!$B$3:$B$731,"<>Software",Source_Evolution!$Q$3:$Q$731,">0")

Sheet By Department
A1: Revenue by Department (£ GBP)
A3: Department | B3: FY2014A | C3: FY2015A | D3: FY2016A | E3: FY2017A | F3: FY2018A | G3: FY2019A | H3: FY2020A | I3: FY2021A | J3: FY2022A | K3: FY2023A | L3: FY2024A | M3: FY2025A | N3: FY2026A | O3: CAGR FY14-FY26
A4: Software | B4: =SUMIFS(Source_Evolution!$E$3:$E$731,Source_Evolution!$B$3:$B$731,"Software") | C4: =SUMIFS(Source_Evolution!$F$3:$F$731,Source_Evolution!$B$3:$B$731,"Software") | D4: =SUMIFS(Source_Evolution!$G$3:$G$731,Source_Evolution!$B$3:$B$731,"Software") | E4: =SUMIFS(Source_Evolution!$H$3:$H$731,Source_Evolution!$B$3:$B$731,"Software") | F4: =SUMIFS(Source_Evolution!$I$3:$I$731,Source_Evolution!$B$3:$B$731,"Software") | G4: =SUMIFS(Source_Evolution!$J$3:$J$731,Source_Evolution!$B$3:$B$731,"Software") | H4: =SUMIFS(Source_Evolution!$K$3:$K$731,Source_Evolution!$B$3:$B$731,"Software") | I4: =SUMIFS(Source_Evolution!$L$3:$L$731,Source_Evolution!$B$3:$B$731,"Software") | J4: =SUMIFS(Source_Evolution!$M$3:$M$731,Source_Evolution!$B$3:$B$731,"Software") | K4: =SUMIFS(Source_Evolution!$N$3:$N$731,Source_Evolution!$B$3:$B$731,"Software") | L4: =SUMIFS(Source_Evolution!$O$3:$O$731,Source_Evolution!$B$3:$B$731,"Software") | M4: =SUMIFS(Source_Evolution!$P$3:$P$731,Source_Evolution!$B$3:$B$731,"Software") | N4: =SUMIFS(Source_Evolution!$Q$3:$Q$731,Source_Evolution!$B$3:$B$731,"Software") | O4: =IFERROR((N4/B4)^(1/12)-1,"-")
A5: Operations | B5: =SUMIFS(Source_Evolution!$E$3:$E$731,Source_Evolution!$B$3:$B$731,"Operations") | C5: =SUMIFS(Source_Evolution!$F$3:$F$731,Source_Evolution!$B$3:$B$731,"Operations") | D5: =SUMIFS(Source_Evolution!$G$3:$G$731,Source_Evolution!$B$3:$B$731,"Operations") | E5: =SUMIFS(Source_Evolution!$H$3:$H$731,Source_Evolution!$B$3:$B$731,"Operations") | F5: =SUMIFS(Source_Evolution!$I$3:$I$731,Source_Evolution!$B$3:$B$731,"Operations") | G5: =SUMIFS(Source_Evolution!$J$3:$J$731,Source_Evolution!$B$3:$B$731,"Operations") | H5: =SUMIFS(Source_Evolution!$K$3:$K$731,Source_Evolution!$B$3:$B$731,"Operations") | I5: =SUMIFS(Source_Evolution!$L$3:$L$731,Source_Evolution!$B$3:$B$731,"Operations") | J5: =SUMIFS(Source_Evolution!$M$3:$M$731,Source_Evolution!$B$3:$B$731,"Operations") | K5: =SUMIFS(Source_Evolution!$N$3:$N$731,Source_Evolution!$B$3:$B$731,"Operations") | L5: =SUMIFS(Source_Evolution!$O$3:$O$731,Source_Evolution!$B$3:$B$731,"Operations") | M5: =SUMIFS(Source_Evolution!$P$3:$P$731,Source_Evolution!$B$3:$B$731,"Operations") | N5: =SUMIFS(Source_Evolution!$Q$3:$Q$731,Source_Evolution!$B$3:$B$731,"Operations") | O5: =IFERROR((N5/B5)^(1/12)-1,"-")
A6: CVA | B6: =SUMIFS(Source_Evolution!$E$3:$E$731,Source_Evolution!$B$3:$B$731,"CVA") | C6: =SUMIFS(Source_Evolution!$F$3:$F$731,Source_Evolution!$B$3:$B$731,"CVA") | D6: =SUMIFS(Source_Evolution!$G$3:$G$731,Source_Evolution!$B$3:$B$731,"CVA") | E6: =SUMIFS(Source_Evolution!$H$3:$H$731,Source_Evolution!$B$3:$B$731,"CVA") | F6: =SUMIFS(Source_Evolution!$I$3:$I$731,Source_Evolution!$B$3:$B$731,"CVA") | G6: =SUMIFS(Source_Evolution!$J$3:$J$731,Source_Evolution!$B$3:$B$731,"CVA") | H6: =SUMIFS(Source_Evolution!$K$3:$K$731,Source_Evolution!$B$3:$B$731,"CVA") | I6: =SUMIFS(Source_Evolution!$L$3:$L$731,Source_Evolution!$B$3:$B$731,"CVA") | J6: =SUMIFS(Source_Evolution!$M$3:$M$731,Source_Evolution!$B$3:$B$731,"CVA") | K6: =SUMIFS(Source_Evolution!$N$3:$N$731,Source_Evolution!$B$3:$B$731,"CVA") | L6: =SUMIFS(Source_Evolution!$O$3:$O$731,Source_Evolution!$B$3:$B$731,"CVA") | M6: =SUMIFS(Source_Evolution!$P$3:$P$731,Source_Evolution!$B$3:$B$731,"CVA") | N6: =SUMIFS(Source_Evolution!$Q$3:$Q$731,Source_Evolution!$B$3:$B$731,"CVA") | O6: =IFERROR((N6/B6)^(1/12)-1,"-")
A7: Power | B7: =SUMIFS(Source_Evolution!$E$3:$E$731,Source_Evolution!$B$3:$B$731,"Power") | C7: =SUMIFS(Source_Evolution!$F$3:$F$731,Source_Evolution!$B$3:$B$731,"Power") | D7: =SUMIFS(Source_Evolution!$G$3:$G$731,Source_Evolution!$B$3:$B$731,"Power") | E7: =SUMIFS(Source_Evolution!$H$3:$H$731,Source_Evolution!$B$3:$B$731,"Power") | F7: =SUMIFS(Source_Evolution!$I$3:$I$731,Source_Evolution!$B$3:$B$731,"Power") | G7: =SUMIFS(Source_Evolution!$J$3:$J$731,Source_Evolution!$B$3:$B$731,"Power") | H7: =SUMIFS(Source_Evolution!$K$3:$K$731,Source_Evolution!$B$3:$B$731,"Power") | I7: =SUMIFS(Source_Evolution!$L$3:$L$731,Source_Evolution!$B$3:$B$731,"Power") | J7: =SUMIFS(Source_Evolution!$M$3:$M$731,Source_Evolution!$B$3:$B$731,"Power") | K7: =SUMIFS(Source_Evolution!$N$3:$N$731,Source_Evolution!$B$3:$B$731,"Power") | L7: =SUMIFS(Source_Evolution!$O$3:$O$731,Source_Evolution!$B$3:$B$731,"Power") | M7: =SUMIFS(Source_Evolution!$P$3:$P$731,Source_Evolution!$B$3:$B$731,"Power") | N7: =SUMIFS(Source_Evolution!$Q$3:$Q$731,Source_Evolution!$B$3:$B$731,"Power") | O7: =IFERROR((N7/B7)^(1/12)-1,"-")
A8: Total | B8: =SUM(B4:B7) | C8: =SUM(C4:C7) | D8: =SUM(D4:D7) | E8: =SUM(E4:E7) | F8: =SUM(F4:F7) | G8: =SUM(G4:G7) | H8: =SUM(H4:H7) | I8: =SUM(I4:I7) | ... N8: =SUM(N4:N7) | O8: =IFERROR((N8/B8)^(1/12)-1,"-")
A10: % Mix
A11: Software | B11: =IFERROR(B4/B8,"-") | C11: =IFERROR(C4/C8,"-") | D11: =IFERROR(D4/D8,"-") | E11: =IFERROR(E4/E8,"-") | F11: =IFERROR(F4/F8,"-") | G11: =IFERROR(G4/G8,"-") | H11: =IFERROR(H4/H8,"-") | I11: =IFERROR(I4/I8,"-") | ... N11: =IFERROR(N4/N8,"-")
A12: Operations | B12: =IFERROR(B5/B8,"-") | C12: =IFERROR(C5/C8,"-") | D12: =IFERROR(D5/D8,"-") | E12: =IFERROR(E5/E8,"-") | F12: =IFERROR(F5/F8,"-") | G12: =IFERROR(G5/G8,"-") | H12: =IFERROR(H5/H8,"-") | I12: =IFERROR(I5/I8,"-") | ... N12: =IFERROR(N5/N8,"-")
A13: CVA | B13: =IFERROR(B6/B8,"-") | C13: =IFERROR(C6/C8,"-") | D13: =IFERROR(D6/D8,"-") | E13: =IFERROR(E6/E8,"-") | F13: =IFERROR(F6/F8,"-") | G13: =IFERROR(G6/G8,"-") | H13: =IFERROR(H6/H8,"-") | I13: =IFERROR(I6/I8,"-") | ... N13: =IFERROR(N6/N8,"-")
A14: Power | B14: =IFERROR(B7/B8,"-") | C14: =IFERROR(C7/C8,"-") | D14: =IFERROR(D7/D8,"-") | E14: =IFERROR(E7/E8,"-") | F14: =IFERROR(F7/F8,"-") | G14: =IFERROR(G7/G8,"-") | H14: =IFERROR(H7/H8,"-") | I14: =IFERROR(I7/I8,"-") | ... N14: =IFERROR(N7/N8,"-")

Sheet By Product
A1: Revenue by Product (£ GBP)
A3: Product | B3: FY2014A | C3: FY2015A | D3: FY2016A | E3: FY2017A | F3: FY2018A | G3: FY2019A | H3: FY2020A | I3: FY2021A | J3: FY2022A | K3: FY2023A | L3: FY2024A | M3: FY2025A | N3: FY2026A | O3: CAGR FY14-FY26 | P3: % of FY26
A4: CVA | B4: =SUMIFS(Source_Evolution!$E$3:$E$731,Source_Evolution!$C$3:$C$731,"CVA") | C4: =SUMIFS(Source_Evolution!$F$3:$F$731,Source_Evolution!$C$3:$C$731,"CVA") | D4: =SUMIFS(Source_Evolution!$G$3:$G$731,Source_Evolution!$C$3:$C$731,"CVA") | E4: =SUMIFS(Source_Evolution!$H$3:$H$731,Source_Evolution!$C$3:$C$731,"CVA") | F4: =SUMIFS(Source_Evolution!$I$3:$I$731,Source_Evolution!$C$3:$C$731,"CVA") | G4: =SUMIFS(Source_Evolution!$J$3:$J$731,Source_Evolution!$C$3:$C$731,"CVA") | H4: =SUMIFS(Source_Evolution!$K$3:$K$731,Source_Evolution!$C$3:$C$731,"CVA") | I4: =SUMIFS(Source_Evolution!$L$3:$L$731,Source_Evolution!$C$3:$C$731,"CVA") | J4: =SUMIFS(Source_Evolution!$M$3:$M$731,Source_Evolution!$C$3:$C$731,"CVA") | K4: =SUMIFS(Source_Evolution!$N$3:$N$731,Source_Evolution!$C$3:$C$731,"CVA") | L4: =SUMIFS(Source_Evolution!$O$3:$O$731,Source_Evolution!$C$3:$C$731,"CVA") | M4: =SUMIFS(Source_Evolution!$P$3:$P$731,Source_Evolution!$C$3:$C$731,"CVA") | N4: =SUMIFS(Source_Evolution!$Q$3:$Q$731,Source_Evolution!$C$3:$C$731,"CVA") | O4: =IFERROR((N4/B4)^(1/12)-1,"-") | P4: =IFERROR(N4/N$23,"-")
A5: Chorus | B5: =SUMIFS(Source_Evolution!$E$3:$E$731,Source_Evolution!$C$3:$C$731,"Chorus") | C5: =SUMIFS(Source_Evolution!$F$3:$F$731,Source_Evolution!$C$3:$C$731,"Chorus") | D5: =SUMIFS(Source_Evolution!$G$3:$G$731,Source_Evolution!$C$3:$C$731,"Chorus") | E5: =SUMIFS(Source_Evolution!$H$3:$H$731,Source_Evolution!$C$3:$C$731,"Chorus") | F5: =SUMIFS(Source_Evolution!$I$3:$I$731,Source_Evolution!$C$3:$C$731,"Chorus") | G5: =SUMIFS(Source_Evolution!$J$3:$J$731,Source_Evolution!$C$3:$C$731,"Chorus") | H5: =SUMIFS(Source_Evolution!$K$3:$K$731,Source_Evolution!$C$3:$C$731,"Chorus") | I5: =SUMIFS(Source_Evolution!$L$3:$L$731,Source_Evolution!$C$3:$C$731,"Chorus") | J5: =SUMIFS(Source_Evolution!$M$3:$M$731,Source_Evolution!$C$3:$C$731,"Chorus") | K5: =SUMIFS(Source_Evolution!$N$3:$N$731,Source_Evolution!$C$3:$C$731,"Chorus") | L5: =SUMIFS(Source_Evolution!$O$3:$O$731,Source_Evolution!$C$3:$C$731,"Chorus") | M5: =SUMIFS(Source_Evolution!$P$3:$P$731,Source_Evolution!$C$3:$C$731,"Chorus") | N5: =SUMIFS(Source_Evolution!$Q$3:$Q$731,Source_Evolution!$C$3:$C$731,"Chorus") | O5: =IFERROR((N5/B5)^(1/12)-1,"-") | P5: =IFERROR(N5/N$23,"-")
A6: CodeRunner | B6: =SUMIFS(Source_Evolution!$E$3:$E$731,Source_Evolution!$C$3:$C$731,"CodeRunner") | C6: =SUMIFS(Source_Evolution!$F$3:$F$731,Source_Evolution!$C$3:$C$731,"CodeRunner") | D6: =SUMIFS(Source_Evolution!$G$3:$G$731,Source_Evolution!$C$3:$C$731,"CodeRunner") | E6: =SUMIFS(Source_Evolution!$H$3:$H$731,Source_Evolution!$C$3:$C$731,"CodeRunner") | F6: =SUMIFS(Source_Evolution!$I$3:$I$731,Source_Evolution!$C$3:$C$731,"CodeRunner") | G6: =SUMIFS(Source_Evolution!$J$3:$J$731,Source_Evolution!$C$3:$C$731,"CodeRunner") | H6: =SUMIFS(Source_Evolution!$K$3:$K$731,Source_Evolution!$C$3:$C$731,"CodeRunner") | I6: =SUMIFS(Source_Evolution!$L$3:$L$731,Source_Evolution!$C$3:$C$731,"CodeRunner") | J6: =SUMIFS(Source_Evolution!$M$3:$M$731,Source_Evolution!$C$3:$C$731,"CodeRunner") | K6: =SUMIFS(Source_Evolution!$N$3:$N$731,Source_Evolution!$C$3:$C$731,"CodeRunner") | L6: =SUMIFS(Source_Evolution!$O$3:$O$731,Source_Evolution!$C$3:$C$731,"CodeRunner") | M6: =SUMIFS(Source_Evolution!$P$3:$P$731,Source_Evolution!$C$3:$C$731,"CodeRunner") | N6: =SUMIFS(Source_Evolution!$Q$3:$Q$731,Source_Evolution!$C$3:$C$731,"CodeRunner") | O6: =IFERROR((N6/B6)^(1/12)-1,"-") | P6: =IFERROR(N6/N$23,"-")
A7: Demand Text | B7: =SUMIFS(Source_Evolution!$E$3:$E$731,Source_Evolution!$C$3:$C$731,"Demand Text") | C7: =SUMIFS(Source_Evolution!$F$3:$F$731,Source_Evolution!$C$3:$C$731,"Demand Text") | D7: =SUMIFS(Source_Evolution!$G$3:$G$731,Source_Evolution!$C$3:$C$731,"Demand Text") | E7: =SUMIFS(Source_Evolution!$H$3:$H$731,Source_Evolution!$C$3:$C$731,"Demand Text") | F7: =SUMIFS(Source_Evolution!$I$3:$I$731,Source_Evolution!$C$3:$C$731,"Demand Text") | G7: =SUMIFS(Source_Evolution!$J$3:$J$731,Source_Evolution!$C$3:$C$731,"Demand Text") | H7: =SUMIFS(Source_Evolution!$K$3:$K$731,Source_Evolution!$C$3:$C$731,"Demand Text") | I7: =SUMIFS(Source_Evolution!$L$3:$L$731,Source_Evolution!$C$3:$C$731,"Demand Text") | J7: =SUMIFS(Source_Evolution!$M$3:$M$731,Source_Evolution!$C$3:$C$731,"Demand Text") | K7: =SUMIFS(Source_Evolution!$N$3:$N$731,Source_Evolution!$C$3:$C$731,"Demand Text") | L7: =SUMIFS(Source_Evolution!$O$3:$O$731,Source_Evolution!$C$3:$C$731,"Demand Text") | M7: =SUMIFS(Source_Evolution!$P$3:$P$731,Source_Evolution!$C$3:$C$731,"Demand Text") | N7: =SUMIFS(Source_Evolution!$Q$3:$Q$731,Source_Evolution!$C$3:$C$731,"Demand Text") | O7: =IFERROR((N7/B7)^(1/12)-1,"-") | P7: =IFERROR(N7/N$23,"-")
A8: ENOM | B8: =SUMIFS(Source_Evolution!$E$3:$E$731,Source_Evolution!$C$3:$C$731,"ENOM") | C8: =SUMIFS(Source_Evolution!$F$3:$F$731,Source_Evolution!$C$3:$C$731,"ENOM") | D8: =SUMIFS(Source_Evolution!$G$3:$G$731,Source_Evolution!$C$3:$C$731,"ENOM") | E8: =SUMIFS(Source_Evolution!$H$3:$H$731,Source_Evolution!$C$3:$C$731,"ENOM") | F8: =SUMIFS(Source_Evolution!$I$3:$I$731,Source_Evolution!$C$3:$C$731,"ENOM") | G8: =SUMIFS(Source_Evolution!$J$3:$J$731,Source_Evolution!$C$3:$C$731,"ENOM") | H8: =SUMIFS(Source_Evolution!$K$3:$K$731,Source_Evolution!$C$3:$C$731,"ENOM") | I8: =SUMIFS(Source_Evolution!$L$3:$L$731,Source_Evolution!$C$3:$C$731,"ENOM") | J8: =SUMIFS(Source_Evolution!$M$3:$M$731,Source_Evolution!$C$3:$C$731,"ENOM") | K8: =SUMIFS(Source_Evolution!$N$3:$N$731,Source_Evolution!$C$3:$C$731,"ENOM") | L8: =SUMIFS(Source_Evolution!$O$3:$O$731,Source_Evolution!$C$3:$C$731,"ENOM") | M8: =SUMIFS(Source_Evolution!$P$3:$P$731,Source_Evolution!$C$3:$C$731,"ENOM") | N8: =SUMIFS(Source_Evolution!$Q$3:$Q$731,Source_Evolution!$C$3:$C$731,"ENOM") | O8: =IFERROR((N8/B8)^(1/12)-1,"-") | P8: =IFERROR(N8/N$23,"-")
A9: ENOM+ | B9: =SUMIFS(Source_Evolution!$E$3:$E$731,Source_Evolution!$C$3:$C$731,"ENOM+") | C9: =SUMIFS(Source_Evolution!$F$3:$F$731,Source_Evolution!$C$3:$C$731,"ENOM+") | D9: =SUMIFS(Source_Evolution!$G$3:$G$731,Source_Evolution!$C$3:$C$731,"ENOM+") | E9: =SUMIFS(Source_Evolution!$H$3:$H$731,Source_Evolution!$C$3:$C$731,"ENOM+") | F9: =SUMIFS(Source_Evolution!$I$3:$I$731,Source_Evolution!$C$3:$C$731,"ENOM+") | G9: =SUMIFS(Source_Evolution!$J$3:$J$731,Source_Evolution!$C$3:$C$731,"ENOM+") | H9: =SUMIFS(Source_Evolution!$K$3:$K$731,Source_Evolution!$C$3:$C$731,"ENOM+") | I9: =SUMIFS(Source_Evolution!$L$3:$L$731,Source_Evolution!$C$3:$C$731,"ENOM+") | J9: =SUMIFS(Source_Evolution!$M$3:$M$731,Source_Evolution!$C$3:$C$731,"ENOM+") | K9: =SUMIFS(Source_Evolution!$N$3:$N$731,Source_Evolution!$C$3:$C$731,"ENOM+") | L9: =SUMIFS(Source_Evolution!$O$3:$O$731,Source_Evolution!$C$3:$C$731,"ENOM+") | M9: =SUMIFS(Source_Evolution!$P$3:$P$731,Source_Evolution!$C$3:$C$731,"ENOM+") | N9: =SUMIFS(Source_Evolution!$Q$3:$Q$731,Source_Evolution!$C$3:$C$731,"ENOM+") | O9: =IFERROR((N9/B9)^(1/12)-1,"-") | P9: =IFERROR(N9/N$23,"-")
A10: EuroRunner | B10: =SUMIFS(Source_Evolution!$E$3:$E$731,Source_Evolution!$C$3:$C$731,"EuroRunner") | C10: =SUMIFS(Source_Evolution!$F$3:$F$731,Source_Evolution!$C$3:$C$731,"EuroRunner") | D10: =SUMIFS(Source_Evolution!$G$3:$G$731,Source_Evolution!$C$3:$C$731,"EuroRunner") | E10: =SUMIFS(Source_Evolution!$H$3:$H$731,Source_Evolution!$C$3:$C$731,"EuroRunner") | F10: =SUMIFS(Source_Evolution!$I$3:$I$731,Source_Evolution!$C$3:$C$731,"EuroRunner") | G10: =SUMIFS(Source_Evolution!$J$3:$J$731,Source_Evolution!$C$3:$C$731,"EuroRunner") | H10: =SUMIFS(Source_Evolution!$K$3:$K$731,Source_Evolution!$C$3:$C$731,"EuroRunner") | I10: =SUMIFS(Source_Evolution!$L$3:$L$731,Source_Evolution!$C$3:$C$731,"EuroRunner") | J10: =SUMIFS(Source_Evolution!$M$3:$M$731,Source_Evolution!$C$3:$C$731,"EuroRunner") | K10: =SUMIFS(Source_Evolution!$N$3:$N$731,Source_Evolution!$C$3:$C$731,"EuroRunner") | L10: =SUMIFS(Source_Evolution!$O$3:$O$731,Source_Evolution!$C$3:$C$731,"EuroRunner") | M10: =SUMIFS(Source_Evolution!$P$3:$P$731,Source_Evolution!$C$3:$C$731,"EuroRunner") | N10: =SUMIFS(Source_Evolution!$Q$3:$Q$731,Source_Evolution!$C$3:$C$731,"EuroRunner") | O10: =IFERROR((N10/B10)^(1/12)-1,"-") | P10: =IFERROR(N10/N$23,"-")
A11: Fluxys Software | B11: =SUMIFS(Source_Evolution!$E$3:$E$731,Source_Evolution!$C$3:$C$731,"Fluxys Software") | C11: =SUMIFS(Source_Evolution!$F$3:$F$731,Source_Evolution!$C$3:$C$731,"Fluxys Software") | D11: =SUMIFS(Source_Evolution!$G$3:$G$731,Source_Evolution!$C$3:$C$731,"Fluxys Software") | E11: =SUMIFS(Source_Evolution!$H$3:$H$731,Source_Evolution!$C$3:$C$731,"Fluxys Software") | F11: =SUMIFS(Source_Evolution!$I$3:$I$731,Source_Evolution!$C$3:$C$731,"Fluxys Software") | G11: =SUMIFS(Source_Evolution!$J$3:$J$731,Source_Evolution!$C$3:$C$731,"Fluxys Software") | H11: =SUMIFS(Source_Evolution!$K$3:$K$731,Source_Evolution!$C$3:$C$731,"Fluxys Software") | I11: =SUMIFS(Source_Evolution!$L$3:$L$731,Source_Evolution!$C$3:$C$731,"Fluxys Software") | J11: =SUMIFS(Source_Evolution!$M$3:$M$731,Source_Evolution!$C$3:$C$731,"Fluxys Software") | K11: =SUMIFS(Source_Evolution!$N$3:$N$731,Source_Evolution!$C$3:$C$731,"Fluxys Software") | L11: =SUMIFS(Source_Evolution!$O$3:$O$731,Source_Evolution!$C$3:$C$731,"Fluxys Software") | M11: =SUMIFS(Source_Evolution!$P$3:$P$731,Source_Evolution!$C$3:$C$731,"Fluxys Software") | N11: =SUMIFS(Source_Evolution!$Q$3:$Q$731,Source_Evolution!$C$3:$C$731,"Fluxys Software") | O11: =IFERROR((N11/B11)^(1/12)-1,"-") | P11: =IFERROR(N11/N$23,"-")
A12: Hosting | B12: =SUMIFS(Source_Evolution!$E$3:$E$731,Source_Evolution!$C$3:$C$731,"Hosting") | C12: =SUMIFS(Source_Evolution!$F$3:$F$731,Source_Evolution!$C$3:$C$731,"Hosting") | D12: =SUMIFS(Source_Evolution!$G$3:$G$731,Source_Evolution!$C$3:$C$731,"Hosting") | E12: =SUMIFS(Source_Evolution!$H$3:$H$731,Source_Evolution!$C$3:$C$731,"Hosting") | F12: =SUMIFS(Source_Evolution!$I$3:$I$731,Source_Evolution!$C$3:$C$731,"Hosting") | G12: =SUMIFS(Source_Evolution!$J$3:$J$731,Source_Evolution!$C$3:$C$731,"Hosting") | H12: =SUMIFS(Source_Evolution!$K$3:$K$731,Source_Evolution!$C$3:$C$731,"Hosting") | I12: =SUMIFS(Source_Evolution!$L$3:$L$731,Source_Evolution!$C$3:$C$731,"Hosting") | J12: =SUMIFS(Source_Evolution!$M$3:$M$731,Source_Evolution!$C$3:$C$731,"Hosting") | K12: =SUMIFS(Source_Evolution!$N$3:$N$731,Source_Evolution!$C$3:$C$731,"Hosting") | L12: =SUMIFS(Source_Evolution!$O$3:$O$731,Source_Evolution!$C$3:$C$731,"Hosting") | M12: =SUMIFS(Source_Evolution!$P$3:$P$731,Source_Evolution!$C$3:$C$731,"Hosting") | N12: =SUMIFS(Source_Evolution!$Q$3:$Q$731,Source_Evolution!$C$3:$C$731,"Hosting") | O12: =IFERROR((N12/B12)^(1/12)-1,"-") | P12: =IFERROR(N12/N$23,"-")
A13: IT Other | B13: =SUMIFS(Source_Evolution!$E$3:$E$731,Source_Evolution!$C$3:$C$731,"IT Other") | C13: =SUMIFS(Source_Evolution!$F$3:$F$731,Source_Evolution!$C$3:$C$731,"IT Other") | D13: =SUMIFS(Source_Evolution!$G$3:$G$731,Source_Evolution!$C$3:$C$731,"IT Other") | E13: =SUMIFS(Source_Evolution!$H$3:$H$731,Source_Evolution!$C$3:$C$731,"IT Other") | F13: =SUMIFS(Source_Evolution!$I$3:$I$731,Source_Evolution!$C$3:$C$731,"IT Other") | G13: =SUMIFS(Source_Evolution!$J$3:$J$731,Source_Evolution!$C$3:$C$731,"IT Other") | H13: =SUMIFS(Source_Evolution!$K$3:$K$731,Source_Evolution!$C$3:$C$731,"IT Other") | I13: =SUMIFS(Source_Evolution!$L$3:$L$731,Source_Evolution!$C$3:$C$731,"IT Other") | J13: =SUMIFS(Source_Evolution!$M$3:$M$731,Source_Evolution!$C$3:$C$731,"IT Other") | K13: =SUMIFS(Source_Evolution!$N$3:$N$731,Source_Evolution!$C$3:$C$731,"IT Other") | L13: =SUMIFS(Source_Evolution!$O$3:$O$731,Source_Evolution!$C$3:$C$731,"IT Other") | M13: =SUMIFS(Source_Evolution!$P$3:$P$731,Source_Evolution!$C$3:$C$731,"IT Other") | N13: =SUMIFS(Source_Evolution!$Q$3:$Q$731,Source_Evolution!$C$3:$C$731,"IT Other") | O13: =IFERROR((N13/B13)^(1/12)-1,"-") | P13: =IFERROR(N13/N$23,"-")
A14: Inform | B14: =SUMIFS(Source_Evolution!$E$3:$E$731,Source_Evolution!$C$3:$C$731,"Inform") | C14: =SUMIFS(Source_Evolution!$F$3:$F$731,Source_Evolution!$C$3:$C$731,"Inform") | D14: =SUMIFS(Source_Evolution!$G$3:$G$731,Source_Evolution!$C$3:$C$731,"Inform") | E14: =SUMIFS(Source_Evolution!$H$3:$H$731,Source_Evolution!$C$3:$C$731,"Inform") | F14: =SUMIFS(Source_Evolution!$I$3:$I$731,Source_Evolution!$C$3:$C$731,"Inform") | G14: =SUMIFS(Source_Evolution!$J$3:$J$731,Source_Evolution!$C$3:$C$731,"Inform") | H14: =SUMIFS(Source_Evolution!$K$3:$K$731,Source_Evolution!$C$3:$C$731,"Inform") | I14: =SUMIFS(Source_Evolution!$L$3:$L$731,Source_Evolution!$C$3:$C$731,"Inform") | J14: =SUMIFS(Source_Evolution!$M$3:$M$731,Source_Evolution!$C$3:$C$731,"Inform") | K14: =SUMIFS(Source_Evolution!$N$3:$N$731,Source_Evolution!$C$3:$C$731,"Inform") | L14: =SUMIFS(Source_Evolution!$O$3:$O$731,Source_Evolution!$C$3:$C$731,"Inform") | M14: =SUMIFS(Source_Evolution!$P$3:$P$731,Source_Evolution!$C$3:$C$731,"Inform") | N14: =SUMIFS(Source_Evolution!$Q$3:$Q$731,Source_Evolution!$C$3:$C$731,"Inform") | O14: =IFERROR((N14/B14)^(1/12)-1,"-") | P14: =IFERROR(N14/N$23,"-")
A15: Market Gas | B15: =SUMIFS(Source_Evolution!$E$3:$E$731,Source_Evolution!$C$3:$C$731,"Market Gas") | C15: =SUMIFS(Source_Evolution!$F$3:$F$731,Source_Evolution!$C$3:$C$731,"Market Gas") | D15: =SUMIFS(Source_Evolution!$G$3:$G$731,Source_Evolution!$C$3:$C$731,"Market Gas") | E15: =SUMIFS(Source_Evolution!$H$3:$H$731,Source_Evolution!$C$3:$C$731,"Market Gas") | F15: =SUMIFS(Source_Evolution!$I$3:$I$731,Source_Evolution!$C$3:$C$731,"Market Gas") | G15: =SUMIFS(Source_Evolution!$J$3:$J$731,Source_Evolution!$C$3:$C$731,"Market Gas") | H15: =SUMIFS(Source_Evolution!$K$3:$K$731,Source_Evolution!$C$3:$C$731,"Market Gas") | I15: =SUMIFS(Source_Evolution!$L$3:$L$731,Source_Evolution!$C$3:$C$731,"Market Gas") | J15: =SUMIFS(Source_Evolution!$M$3:$M$731,Source_Evolution!$C$3:$C$731,"Market Gas") | K15: =SUMIFS(Source_Evolution!$N$3:$N$731,Source_Evolution!$C$3:$C$731,"Market Gas") | L15: =SUMIFS(Source_Evolution!$O$3:$O$731,Source_Evolution!$C$3:$C$731,"Market Gas") | M15: =SUMIFS(Source_Evolution!$P$3:$P$731,Source_Evolution!$C$3:$C$731,"Market Gas") | N15: =SUMIFS(Source_Evolution!$Q$3:$Q$731,Source_Evolution!$C$3:$C$731,"Market Gas") | O15: =IFERROR((N15/B15)^(1/12)-1,"-") | P15: =IFERROR(N15/N$23,"-")
A16: Market Power | B16: =SUMIFS(Source_Evolution!$E$3:$E$731,Source_Evolution!$C$3:$C$731,"Market Power") | C16: =SUMIFS(Source_Evolution!$F$3:$F$731,Source_Evolution!$C$3:$C$731,"Market Power") | D16: =SUMIFS(Source_Evolution!$G$3:$G$731,Source_Evolution!$C$3:$C$731,"Market Power") | E16: =SUMIFS(Source_Evolution!$H$3:$H$731,Source_Evolution!$C$3:$C$731,"Market Power") | F16: =SUMIFS(Source_Evolution!$I$3:$I$731,Source_Evolution!$C$3:$C$731,"Market Power") | G16: =SUMIFS(Source_Evolution!$J$3:$J$731,Source_Evolution!$C$3:$C$731,"Market Power") | H16: =SUMIFS(Source_Evolution!$K$3:$K$731,Source_Evolution!$C$3:$C$731,"Market Power") | I16: =SUMIFS(Source_Evolution!$L$3:$L$731,Source_Evolution!$C$3:$C$731,"Market Power") | J16: =SUMIFS(Source_Evolution!$M$3:$M$731,Source_Evolution!$C$3:$C$731,"Market Power") | K16: =SUMIFS(Source_Evolution!$N$3:$N$731,Source_Evolution!$C$3:$C$731,"Market Power") | L16: =SUMIFS(Source_Evolution!$O$3:$O$731,Source_Evolution!$C$3:$C$731,"Market Power") | M16: =SUMIFS(Source_Evolution!$P$3:$P$731,Source_Evolution!$C$3:$C$731,"Market Power") | N16: =SUMIFS(Source_Evolution!$Q$3:$Q$731,Source_Evolution!$C$3:$C$731,"Market Power") | O16: =IFERROR((N16/B16)^(1/12)-1,"-") | P16: =IFERROR(N16/N$23,"-")
A17: Operations Other | B17: =SUMIFS(Source_Evolution!$E$3:$E$731,Source_Evolution!$C$3:$C$731,"Operations Other") | C17: =SUMIFS(Source_Evolution!$F$3:$F$731,Source_Evolution!$C$3:$C$731,"Operations Other") | D17: =SUMIFS(Source_Evolution!$G$3:$G$731,Source_Evolution!$C$3:$C$731,"Operations Other") | E17: =SUMIFS(Source_Evolution!$H$3:$H$731,Source_Evolution!$C$3:$C$731,"Operations Other") | F17: =SUMIFS(Source_Evolution!$I$3:$I$731,Source_Evolution!$C$3:$C$731,"Operations Other") | G17: =SUMIFS(Source_Evolution!$J$3:$J$731,Source_Evolution!$C$3:$C$731,"Operations Other") | H17: =SUMIFS(Source_Evolution!$K$3:$K$731,Source_Evolution!$C$3:$C$731,"Operations Other") | I17: =SUMIFS(Source_Evolution!$L$3:$L$731,Source_Evolution!$C$3:$C$731,"Operations Other") | J17: =SUMIFS(Source_Evolution!$M$3:$M$731,Source_Evolution!$C$3:$C$731,"Operations Other") | K17: =SUMIFS(Source_Evolution!$N$3:$N$731,Source_Evolution!$C$3:$C$731,"Operations Other") | L17: =SUMIFS(Source_Evolution!$O$3:$O$731,Source_Evolution!$C$3:$C$731,"Operations Other") | M17: =SUMIFS(Source_Evolution!$P$3:$P$731,Source_Evolution!$C$3:$C$731,"Operations Other") | N17: =SUMIFS(Source_Evolution!$Q$3:$Q$731,Source_Evolution!$C$3:$C$731,"Operations Other") | O17: =IFERROR((N17/B17)^(1/12)-1,"-") | P17: =IFERROR(N17/N$23,"-")
A18: PowerTrak | B18: =SUMIFS(Source_Evolution!$E$3:$E$731,Source_Evolution!$C$3:$C$731,"PowerTrak") | C18: =SUMIFS(Source_Evolution!$F$3:$F$731,Source_Evolution!$C$3:$C$731,"PowerTrak") | D18: =SUMIFS(Source_Evolution!$G$3:$G$731,Source_Evolution!$C$3:$C$731,"PowerTrak") | E18: =SUMIFS(Source_Evolution!$H$3:$H$731,Source_Evolution!$C$3:$C$731,"PowerTrak") | F18: =SUMIFS(Source_Evolution!$I$3:$I$731,Source_Evolution!$C$3:$C$731,"PowerTrak") | G18: =SUMIFS(Source_Evolution!$J$3:$J$731,Source_Evolution!$C$3:$C$731,"PowerTrak") | H18: =SUMIFS(Source_Evolution!$K$3:$K$731,Source_Evolution!$C$3:$C$731,"PowerTrak") | I18: =SUMIFS(Source_Evolution!$L$3:$L$731,Source_Evolution!$C$3:$C$731,"PowerTrak") | J18: =SUMIFS(Source_Evolution!$M$3:$M$731,Source_Evolution!$C$3:$C$731,"PowerTrak") | K18: =SUMIFS(Source_Evolution!$N$3:$N$731,Source_Evolution!$C$3:$C$731,"PowerTrak") | L18: =SUMIFS(Source_Evolution!$O$3:$O$731,Source_Evolution!$C$3:$C$731,"PowerTrak") | M18: =SUMIFS(Source_Evolution!$P$3:$P$731,Source_Evolution!$C$3:$C$731,"PowerTrak") | N18: =SUMIFS(Source_Evolution!$Q$3:$Q$731,Source_Evolution!$C$3:$C$731,"PowerTrak") | O18: =IFERROR((N18/B18)^(1/12)-1,"-") | P18: =IFERROR(N18/N$23,"-")
A19: Routing | B19: =SUMIFS(Source_Evolution!$E$3:$E$731,Source_Evolution!$C$3:$C$731,"Routing") | C19: =SUMIFS(Source_Evolution!$F$3:$F$731,Source_Evolution!$C$3:$C$731,"Routing") | D19: =SUMIFS(Source_Evolution!$G$3:$G$731,Source_Evolution!$C$3:$C$731,"Routing") | E19: =SUMIFS(Source_Evolution!$H$3:$H$731,Source_Evolution!$C$3:$C$731,"Routing") | F19: =SUMIFS(Source_Evolution!$I$3:$I$731,Source_Evolution!$C$3:$C$731,"Routing") | G19: =SUMIFS(Source_Evolution!$J$3:$J$731,Source_Evolution!$C$3:$C$731,"Routing") | H19: =SUMIFS(Source_Evolution!$K$3:$K$731,Source_Evolution!$C$3:$C$731,"Routing") | I19: =SUMIFS(Source_Evolution!$L$3:$L$731,Source_Evolution!$C$3:$C$731,"Routing") | J19: =SUMIFS(Source_Evolution!$M$3:$M$731,Source_Evolution!$C$3:$C$731,"Routing") | K19: =SUMIFS(Source_Evolution!$N$3:$N$731,Source_Evolution!$C$3:$C$731,"Routing") | L19: =SUMIFS(Source_Evolution!$O$3:$O$731,Source_Evolution!$C$3:$C$731,"Routing") | M19: =SUMIFS(Source_Evolution!$P$3:$P$731,Source_Evolution!$C$3:$C$731,"Routing") | N19: =SUMIFS(Source_Evolution!$Q$3:$Q$731,Source_Evolution!$C$3:$C$731,"Routing") | O19: =IFERROR((N19/B19)^(1/12)-1,"-") | P19: =IFERROR(N19/N$23,"-")
A20: Shipper Gas | B20: =SUMIFS(Source_Evolution!$E$3:$E$731,Source_Evolution!$C$3:$C$731,"Shipper Gas") | C20: =SUMIFS(Source_Evolution!$F$3:$F$731,Source_Evolution!$C$3:$C$731,"Shipper Gas") | D20: =SUMIFS(Source_Evolution!$G$3:$G$731,Source_Evolution!$C$3:$C$731,"Shipper Gas") | E20: =SUMIFS(Source_Evolution!$H$3:$H$731,Source_Evolution!$C$3:$C$731,"Shipper Gas") | F20: =SUMIFS(Source_Evolution!$I$3:$I$731,Source_Evolution!$C$3:$C$731,"Shipper Gas") | G20: =SUMIFS(Source_Evolution!$J$3:$J$731,Source_Evolution!$C$3:$C$731,"Shipper Gas") | H20: =SUMIFS(Source_Evolution!$K$3:$K$731,Source_Evolution!$C$3:$C$731,"Shipper Gas") | I20: =SUMIFS(Source_Evolution!$L$3:$L$731,Source_Evolution!$C$3:$C$731,"Shipper Gas") | J20: =SUMIFS(Source_Evolution!$M$3:$M$731,Source_Evolution!$C$3:$C$731,"Shipper Gas") | K20: =SUMIFS(Source_Evolution!$N$3:$N$731,Source_Evolution!$C$3:$C$731,"Shipper Gas") | L20: =SUMIFS(Source_Evolution!$O$3:$O$731,Source_Evolution!$C$3:$C$731,"Shipper Gas") | M20: =SUMIFS(Source_Evolution!$P$3:$P$731,Source_Evolution!$C$3:$C$731,"Shipper Gas") | N20: =SUMIFS(Source_Evolution!$Q$3:$Q$731,Source_Evolution!$C$3:$C$731,"Shipper Gas") | O20: =IFERROR((N20/B20)^(1/12)-1,"-") | P20: =IFERROR(N20/N$23,"-")
A21: Shipper Power | B21: =SUMIFS(Source_Evolution!$E$3:$E$731,Source_Evolution!$C$3:$C$731,"Shipper Power") | C21: =SUMIFS(Source_Evolution!$F$3:$F$731,Source_Evolution!$C$3:$C$731,"Shipper Power") | D21: =SUMIFS(Source_Evolution!$G$3:$G$731,Source_Evolution!$C$3:$C$731,"Shipper Power") | E21: =SUMIFS(Source_Evolution!$H$3:$H$731,Source_Evolution!$C$3:$C$731,"Shipper Power") | F21: =SUMIFS(Source_Evolution!$I$3:$I$731,Source_Evolution!$C$3:$C$731,"Shipper Power") | G21: =SUMIFS(Source_Evolution!$J$3:$J$731,Source_Evolution!$C$3:$C$731,"Shipper Power") | H21: =SUMIFS(Source_Evolution!$K$3:$K$731,Source_Evolution!$C$3:$C$731,"Shipper Power") | I21: =SUMIFS(Source_Evolution!$L$3:$L$731,Source_Evolution!$C$3:$C$731,"Shipper Power") | J21: =SUMIFS(Source_Evolution!$M$3:$M$731,Source_Evolution!$C$3:$C$731,"Shipper Power") | K21: =SUMIFS(Source_Evolution!$N$3:$N$731,Source_Evolution!$C$3:$C$731,"Shipper Power") | L21: =SUMIFS(Source_Evolution!$O$3:$O$731,Source_Evolution!$C$3:$C$731,"Shipper Power") | M21: =SUMIFS(Source_Evolution!$P$3:$P$731,Source_Evolution!$C$3:$C$731,"Shipper Power") | N21: =SUMIFS(Source_Evolution!$Q$3:$Q$731,Source_Evolution!$C$3:$C$731,"Shipper Power") | O21: =IFERROR((N21/B21)^(1/12)-1,"-") | P21: =IFERROR(N21/N$23,"-")
A22: Training | B22: =SUMIFS(Source_Evolution!$E$3:$E$731,Source_Evolution!$C$3:$C$731,"Training") | C22: =SUMIFS(Source_Evolution!$F$3:$F$731,Source_Evolution!$C$3:$C$731,"Training") | D22: =SUMIFS(Source_Evolution!$G$3:$G$731,Source_Evolution!$C$3:$C$731,"Training") | E22: =SUMIFS(Source_Evolution!$H$3:$H$731,Source_Evolution!$C$3:$C$731,"Training") | F22: =SUMIFS(Source_Evolution!$I$3:$I$731,Source_Evolution!$C$3:$C$731,"Training") | G22: =SUMIFS(Source_Evolution!$J$3:$J$731,Source_Evolution!$C$3:$C$731,"Training") | H22: =SUMIFS(Source_Evolution!$K$3:$K$731,Source_Evolution!$C$3:$C$731,"Training") | I22: =SUMIFS(Source_Evolution!$L$3:$L$731,Source_Evolution!$C$3:$C$731,"Training") | J22: =SUMIFS(Source_Evolution!$M$3:$M$731,Source_Evolution!$C$3:$C$731,"Training") | K22: =SUMIFS(Source_Evolution!$N$3:$N$731,Source_Evolution!$C$3:$C$731,"Training") | L22: =SUMIFS(Source_Evolution!$O$3:$O$731,Source_Evolution!$C$3:$C$731,"Training") | M22: =SUMIFS(Source_Evolution!$P$3:$P$731,Source_Evolution!$C$3:$C$731,"Training") | N22: =SUMIFS(Source_Evolution!$Q$3:$Q$731,Source_Evolution!$C$3:$C$731,"Training") | O22: =IFERROR((N22/B22)^(1/12)-1,"-") | P22: =IFERROR(N22/N$23,"-")
A23: Total | B23: =SUM(B4:B22) | C23: =SUM(C4:C22) | D23: =SUM(D4:D22) | E23: =SUM(E4:E22) | F23: =SUM(F4:F22) | G23: =SUM(G4:G22) | H23: =SUM(H4:H22) | I23: =SUM(I4:I22) | ... N23: =SUM(N4:N22) | O23: =IFERROR((N23/B23)^(1/12)-1,"-") | P23: =IFERROR(N23/N23,"-")

Sheet By Geography
A1: Revenue by Country (£ GBP)
A3: Country | B3: FY2014A | C3: FY2015A | D3: FY2016A | E3: FY2017A | F3: FY2018A | G3: FY2019A | H3: FY2020A | I3: FY2021A | J3: FY2022A | K3: FY2023A | L3: FY2024A | M3: FY2025A | N3: FY2026A | O3: CAGR FY14-FY26 | P3: % of FY26
A4: Austria | B4: =SUMIFS(Source_Evolution!$E$3:$E$731,Source_Evolution!$D$3:$D$731,"Austria") | C4: =SUMIFS(Source_Evolution!$F$3:$F$731,Source_Evolution!$D$3:$D$731,"Austria") | D4: =SUMIFS(Source_Evolution!$G$3:$G$731,Source_Evolution!$D$3:$D$731,"Austria") | E4: =SUMIFS(Source_Evolution!$H$3:$H$731,Source_Evolution!$D$3:$D$731,"Austria") | F4: =SUMIFS(Source_Evolution!$I$3:$I$731,Source_Evolution!$D$3:$D$731,"Austria") | G4: =SUMIFS(Source_Evolution!$J$3:$J$731,Source_Evolution!$D$3:$D$731,"Austria") | H4: =SUMIFS(Source_Evolution!$K$3:$K$731,Source_Evolution!$D$3:$D$731,"Austria") | I4: =SUMIFS(Source_Evolution!$L$3:$L$731,Source_Evolution!$D$3:$D$731,"Austria") | J4: =SUMIFS(Source_Evolution!$M$3:$M$731,Source_Evolution!$D$3:$D$731,"Austria") | K4: =SUMIFS(Source_Evolution!$N$3:$N$731,Source_Evolution!$D$3:$D$731,"Austria") | L4: =SUMIFS(Source_Evolution!$O$3:$O$731,Source_Evolution!$D$3:$D$731,"Austria") | M4: =SUMIFS(Source_Evolution!$P$3:$P$731,Source_Evolution!$D$3:$D$731,"Austria") | N4: =SUMIFS(Source_Evolution!$Q$3:$Q$731,Source_Evolution!$D$3:$D$731,"Austria") | O4: =IFERROR((N4/B4)^(1/12)-1,"-") | P4: =IFERROR(N4/N$28,"-")
A5: Belgium | B5: =SUMIFS(Source_Evolution!$E$3:$E$731,Source_Evolution!$D$3:$D$731,"Belgium") | C5: =SUMIFS(Source_Evolution!$F$3:$F$731,Source_Evolution!$D$3:$D$731,"Belgium") | D5: =SUMIFS(Source_Evolution!$G$3:$G$731,Source_Evolution!$D$3:$D$731,"Belgium") | E5: =SUMIFS(Source_Evolution!$H$3:$H$731,Source_Evolution!$D$3:$D$731,"Belgium") | F5: =SUMIFS(Source_Evolution!$I$3:$I$731,Source_Evolution!$D$3:$D$731,"Belgium") | G5: =SUMIFS(Source_Evolution!$J$3:$J$731,Source_Evolution!$D$3:$D$731,"Belgium") | H5: =SUMIFS(Source_Evolution!$K$3:$K$731,Source_Evolution!$D$3:$D$731,"Belgium") | I5: =SUMIFS(Source_Evolution!$L$3:$L$731,Source_Evolution!$D$3:$D$731,"Belgium") | J5: =SUMIFS(Source_Evolution!$M$3:$M$731,Source_Evolution!$D$3:$D$731,"Belgium") | K5: =SUMIFS(Source_Evolution!$N$3:$N$731,Source_Evolution!$D$3:$D$731,"Belgium") | L5: =SUMIFS(Source_Evolution!$O$3:$O$731,Source_Evolution!$D$3:$D$731,"Belgium") | M5: =SUMIFS(Source_Evolution!$P$3:$P$731,Source_Evolution!$D$3:$D$731,"Belgium") | N5: =SUMIFS(Source_Evolution!$Q$3:$Q$731,Source_Evolution!$D$3:$D$731,"Belgium") | O5: =IFERROR((N5/B5)^(1/12)-1,"-") | P5: =IFERROR(N5/N$28,"-")
A6: Czech Republic | B6: =SUMIFS(Source_Evolution!$E$3:$E$731,Source_Evolution!$D$3:$D$731,"Czech Republic") | C6: =SUMIFS(Source_Evolution!$F$3:$F$731,Source_Evolution!$D$3:$D$731,"Czech Republic") | D6: =SUMIFS(Source_Evolution!$G$3:$G$731,Source_Evolution!$D$3:$D$731,"Czech Republic") | E6: =SUMIFS(Source_Evolution!$H$3:$H$731,Source_Evolution!$D$3:$D$731,"Czech Republic") | F6: =SUMIFS(Source_Evolution!$I$3:$I$731,Source_Evolution!$D$3:$D$731,"Czech Republic") | G6: =SUMIFS(Source_Evolution!$J$3:$J$731,Source_Evolution!$D$3:$D$731,"Czech Republic") | H6: =SUMIFS(Source_Evolution!$K$3:$K$731,Source_Evolution!$D$3:$D$731,"Czech Republic") | I6: =SUMIFS(Source_Evolution!$L$3:$L$731,Source_Evolution!$D$3:$D$731,"Czech Republic") | J6: =SUMIFS(Source_Evolution!$M$3:$M$731,Source_Evolution!$D$3:$D$731,"Czech Republic") | K6: =SUMIFS(Source_Evolution!$N$3:$N$731,Source_Evolution!$D$3:$D$731,"Czech Republic") | L6: =SUMIFS(Source_Evolution!$O$3:$O$731,Source_Evolution!$D$3:$D$731,"Czech Republic") | M6: =SUMIFS(Source_Evolution!$P$3:$P$731,Source_Evolution!$D$3:$D$731,"Czech Republic") | N6: =SUMIFS(Source_Evolution!$Q$3:$Q$731,Source_Evolution!$D$3:$D$731,"Czech Republic") | O6: =IFERROR((N6/B6)^(1/12)-1,"-") | P6: =IFERROR(N6/N$28,"-")
A7: Denmark | B7: =SUMIFS(Source_Evolution!$E$3:$E$731,Source_Evolution!$D$3:$D$731,"Denmark") | C7: =SUMIFS(Source_Evolution!$F$3:$F$731,Source_Evolution!$D$3:$D$731,"Denmark") | D7: =SUMIFS(Source_Evolution!$G$3:$G$731,Source_Evolution!$D$3:$D$731,"Denmark") | E7: =SUMIFS(Source_Evolution!$H$3:$H$731,Source_Evolution!$D$3:$D$731,"Denmark") | F7: =SUMIFS(Source_Evolution!$I$3:$I$731,Source_Evolution!$D$3:$D$731,"Denmark") | G7: =SUMIFS(Source_Evolution!$J$3:$J$731,Source_Evolution!$D$3:$D$731,"Denmark") | H7: =SUMIFS(Source_Evolution!$K$3:$K$731,Source_Evolution!$D$3:$D$731,"Denmark") | I7: =SUMIFS(Source_Evolution!$L$3:$L$731,Source_Evolution!$D$3:$D$731,"Denmark") | J7: =SUMIFS(Source_Evolution!$M$3:$M$731,Source_Evolution!$D$3:$D$731,"Denmark") | K7: =SUMIFS(Source_Evolution!$N$3:$N$731,Source_Evolution!$D$3:$D$731,"Denmark") | L7: =SUMIFS(Source_Evolution!$O$3:$O$731,Source_Evolution!$D$3:$D$731,"Denmark") | M7: =SUMIFS(Source_Evolution!$P$3:$P$731,Source_Evolution!$D$3:$D$731,"Denmark") | N7: =SUMIFS(Source_Evolution!$Q$3:$Q$731,Source_Evolution!$D$3:$D$731,"Denmark") | O7: =IFERROR((N7/B7)^(1/12)-1,"-") | P7: =IFERROR(N7/N$28,"-")
A8: France | B8: =SUMIFS(Source_Evolution!$E$3:$E$731,Source_Evolution!$D$3:$D$731,"France") | C8: =SUMIFS(Source_Evolution!$F$3:$F$731,Source_Evolution!$D$3:$D$731,"France") | D8: =SUMIFS(Source_Evolution!$G$3:$G$731,Source_Evolution!$D$3:$D$731,"France") | E8: =SUMIFS(Source_Evolution!$H$3:$H$731,Source_Evolution!$D$3:$D$731,"France") | F8: =SUMIFS(Source_Evolution!$I$3:$I$731,Source_Evolution!$D$3:$D$731,"France") | G8: =SUMIFS(Source_Evolution!$J$3:$J$731,Source_Evolution!$D$3:$D$731,"France") | H8: =SUMIFS(Source_Evolution!$K$3:$K$731,Source_Evolution!$D$3:$D$731,"France") | I8: =SUMIFS(Source_Evolution!$L$3:$L$731,Source_Evolution!$D$3:$D$731,"France") | J8: =SUMIFS(Source_Evolution!$M$3:$M$731,Source_Evolution!$D$3:$D$731,"France") | K8: =SUMIFS(Source_Evolution!$N$3:$N$731,Source_Evolution!$D$3:$D$731,"France") | L8: =SUMIFS(Source_Evolution!$O$3:$O$731,Source_Evolution!$D$3:$D$731,"France") | M8: =SUMIFS(Source_Evolution!$P$3:$P$731,Source_Evolution!$D$3:$D$731,"France") | N8: =SUMIFS(Source_Evolution!$Q$3:$Q$731,Source_Evolution!$D$3:$D$731,"France") | O8: =IFERROR((N8/B8)^(1/12)-1,"-") | P8: =IFERROR(N8/N$28,"-")
A9: Germany | B9: =SUMIFS(Source_Evolution!$E$3:$E$731,Source_Evolution!$D$3:$D$731,"Germany") | C9: =SUMIFS(Source_Evolution!$F$3:$F$731,Source_Evolution!$D$3:$D$731,"Germany") | D9: =SUMIFS(Source_Evolution!$G$3:$G$731,Source_Evolution!$D$3:$D$731,"Germany") | E9: =SUMIFS(Source_Evolution!$H$3:$H$731,Source_Evolution!$D$3:$D$731,"Germany") | F9: =SUMIFS(Source_Evolution!$I$3:$I$731,Source_Evolution!$D$3:$D$731,"Germany") | G9: =SUMIFS(Source_Evolution!$J$3:$J$731,Source_Evolution!$D$3:$D$731,"Germany") | H9: =SUMIFS(Source_Evolution!$K$3:$K$731,Source_Evolution!$D$3:$D$731,"Germany") | I9: =SUMIFS(Source_Evolution!$L$3:$L$731,Source_Evolution!$D$3:$D$731,"Germany") | J9: =SUMIFS(Source_Evolution!$M$3:$M$731,Source_Evolution!$D$3:$D$731,"Germany") | K9: =SUMIFS(Source_Evolution!$N$3:$N$731,Source_Evolution!$D$3:$D$731,"Germany") | L9: =SUMIFS(Source_Evolution!$O$3:$O$731,Source_Evolution!$D$3:$D$731,"Germany") | M9: =SUMIFS(Source_Evolution!$P$3:$P$731,Source_Evolution!$D$3:$D$731,"Germany") | N9: =SUMIFS(Source_Evolution!$Q$3:$Q$731,Source_Evolution!$D$3:$D$731,"Germany") | O9: =IFERROR((N9/B9)^(1/12)-1,"-") | P9: =IFERROR(N9/N$28,"-")
A10: Hungary | B10: =SUMIFS(Source_Evolution!$E$3:$E$731,Source_Evolution!$D$3:$D$731,"Hungary") | C10: =SUMIFS(Source_Evolution!$F$3:$F$731,Source_Evolution!$D$3:$D$731,"Hungary") | D10: =SUMIFS(Source_Evolution!$G$3:$G$731,Source_Evolution!$D$3:$D$731,"Hungary") | E10: =SUMIFS(Source_Evolution!$H$3:$H$731,Source_Evolution!$D$3:$D$731,"Hungary") | F10: =SUMIFS(Source_Evolution!$I$3:$I$731,Source_Evolution!$D$3:$D$731,"Hungary") | G10: =SUMIFS(Source_Evolution!$J$3:$J$731,Source_Evolution!$D$3:$D$731,"Hungary") | H10: =SUMIFS(Source_Evolution!$K$3:$K$731,Source_Evolution!$D$3:$D$731,"Hungary") | I10: =SUMIFS(Source_Evolution!$L$3:$L$731,Source_Evolution!$D$3:$D$731,"Hungary") | J10: =SUMIFS(Source_Evolution!$M$3:$M$731,Source_Evolution!$D$3:$D$731,"Hungary") | K10: =SUMIFS(Source_Evolution!$N$3:$N$731,Source_Evolution!$D$3:$D$731,"Hungary") | L10: =SUMIFS(Source_Evolution!$O$3:$O$731,Source_Evolution!$D$3:$D$731,"Hungary") | M10: =SUMIFS(Source_Evolution!$P$3:$P$731,Source_Evolution!$D$3:$D$731,"Hungary") | N10: =SUMIFS(Source_Evolution!$Q$3:$Q$731,Source_Evolution!$D$3:$D$731,"Hungary") | O10: =IFERROR((N10/B10)^(1/12)-1,"-") | P10: =IFERROR(N10/N$28,"-")
A11: Ireland | B11: =SUMIFS(Source_Evolution!$E$3:$E$731,Source_Evolution!$D$3:$D$731,"Ireland") | C11: =SUMIFS(Source_Evolution!$F$3:$F$731,Source_Evolution!$D$3:$D$731,"Ireland") | D11: =SUMIFS(Source_Evolution!$G$3:$G$731,Source_Evolution!$D$3:$D$731,"Ireland") | E11: =SUMIFS(Source_Evolution!$H$3:$H$731,Source_Evolution!$D$3:$D$731,"Ireland") | F11: =SUMIFS(Source_Evolution!$I$3:$I$731,Source_Evolution!$D$3:$D$731,"Ireland") | G11: =SUMIFS(Source_Evolution!$J$3:$J$731,Source_Evolution!$D$3:$D$731,"Ireland") | H11: =SUMIFS(Source_Evolution!$K$3:$K$731,Source_Evolution!$D$3:$D$731,"Ireland") | I11: =SUMIFS(Source_Evolution!$L$3:$L$731,Source_Evolution!$D$3:$D$731,"Ireland") | J11: =SUMIFS(Source_Evolution!$M$3:$M$731,Source_Evolution!$D$3:$D$731,"Ireland") | K11: =SUMIFS(Source_Evolution!$N$3:$N$731,Source_Evolution!$D$3:$D$731,"Ireland") | L11: =SUMIFS(Source_Evolution!$O$3:$O$731,Source_Evolution!$D$3:$D$731,"Ireland") | M11: =SUMIFS(Source_Evolution!$P$3:$P$731,Source_Evolution!$D$3:$D$731,"Ireland") | N11: =SUMIFS(Source_Evolution!$Q$3:$Q$731,Source_Evolution!$D$3:$D$731,"Ireland") | O11: =IFERROR((N11/B11)^(1/12)-1,"-") | P11: =IFERROR(N11/N$28,"-")
A12: Isle of Man | B12: =SUMIFS(Source_Evolution!$E$3:$E$731,Source_Evolution!$D$3:$D$731,"Isle of Man") | C12: =SUMIFS(Source_Evolution!$F$3:$F$731,Source_Evolution!$D$3:$D$731,"Isle of Man") | D12: =SUMIFS(Source_Evolution!$G$3:$G$731,Source_Evolution!$D$3:$D$731,"Isle of Man") | E12: =SUMIFS(Source_Evolution!$H$3:$H$731,Source_Evolution!$D$3:$D$731,"Isle of Man") | F12: =SUMIFS(Source_Evolution!$I$3:$I$731,Source_Evolution!$D$3:$D$731,"Isle of Man") | G12: =SUMIFS(Source_Evolution!$J$3:$J$731,Source_Evolution!$D$3:$D$731,"Isle of Man") | H12: =SUMIFS(Source_Evolution!$K$3:$K$731,Source_Evolution!$D$3:$D$731,"Isle of Man") | I12: =SUMIFS(Source_Evolution!$L$3:$L$731,Source_Evolution!$D$3:$D$731,"Isle of Man") | J12: =SUMIFS(Source_Evolution!$M$3:$M$731,Source_Evolution!$D$3:$D$731,"Isle of Man") | K12: =SUMIFS(Source_Evolution!$N$3:$N$731,Source_Evolution!$D$3:$D$731,"Isle of Man") | L12: =SUMIFS(Source_Evolution!$O$3:$O$731,Source_Evolution!$D$3:$D$731,"Isle of Man") | M12: =SUMIFS(Source_Evolution!$P$3:$P$731,Source_Evolution!$D$3:$D$731,"Isle of Man") | N12: =SUMIFS(Source_Evolution!$Q$3:$Q$731,Source_Evolution!$D$3:$D$731,"Isle of Man") | O12: =IFERROR((N12/B12)^(1/12)-1,"-") | P12: =IFERROR(N12/N$28,"-")
A13: Italy | B13: =SUMIFS(Source_Evolution!$E$3:$E$731,Source_Evolution!$D$3:$D$731,"Italy") | C13: =SUMIFS(Source_Evolution!$F$3:$F$731,Source_Evolution!$D$3:$D$731,"Italy") | D13: =SUMIFS(Source_Evolution!$G$3:$G$731,Source_Evolution!$D$3:$D$731,"Italy") | E13: =SUMIFS(Source_Evolution!$H$3:$H$731,Source_Evolution!$D$3:$D$731,"Italy") | F13: =SUMIFS(Source_Evolution!$I$3:$I$731,Source_Evolution!$D$3:$D$731,"Italy") | G13: =SUMIFS(Source_Evolution!$J$3:$J$731,Source_Evolution!$D$3:$D$731,"Italy") | H13: =SUMIFS(Source_Evolution!$K$3:$K$731,Source_Evolution!$D$3:$D$731,"Italy") | I13: =SUMIFS(Source_Evolution!$L$3:$L$731,Source_Evolution!$D$3:$D$731,"Italy") | J13: =SUMIFS(Source_Evolution!$M$3:$M$731,Source_Evolution!$D$3:$D$731,"Italy") | K13: =SUMIFS(Source_Evolution!$N$3:$N$731,Source_Evolution!$D$3:$D$731,"Italy") | L13: =SUMIFS(Source_Evolution!$O$3:$O$731,Source_Evolution!$D$3:$D$731,"Italy") | M13: =SUMIFS(Source_Evolution!$P$3:$P$731,Source_Evolution!$D$3:$D$731,"Italy") | N13: =SUMIFS(Source_Evolution!$Q$3:$Q$731,Source_Evolution!$D$3:$D$731,"Italy") | O13: =IFERROR((N13/B13)^(1/12)-1,"-") | P13: =IFERROR(N13/N$28,"-")
A14: Luxembourg | B14: =SUMIFS(Source_Evolution!$E$3:$E$731,Source_Evolution!$D$3:$D$731,"Luxembourg") | C14: =SUMIFS(Source_Evolution!$F$3:$F$731,Source_Evolution!$D$3:$D$731,"Luxembourg") | D14: =SUMIFS(Source_Evolution!$G$3:$G$731,Source_Evolution!$D$3:$D$731,"Luxembourg") | E14: =SUMIFS(Source_Evolution!$H$3:$H$731,Source_Evolution!$D$3:$D$731,"Luxembourg") | F14: =SUMIFS(Source_Evolution!$I$3:$I$731,Source_Evolution!$D$3:$D$731,"Luxembourg") | G14: =SUMIFS(Source_Evolution!$J$3:$J$731,Source_Evolution!$D$3:$D$731,"Luxembourg") | H14: =SUMIFS(Source_Evolution!$K$3:$K$731,Source_Evolution!$D$3:$D$731,"Luxembourg") | I14: =SUMIFS(Source_Evolution!$L$3:$L$731,Source_Evolution!$D$3:$D$731,"Luxembourg") | J14: =SUMIFS(Source_Evolution!$M$3:$M$731,Source_Evolution!$D$3:$D$731,"Luxembourg") | K14: =SUMIFS(Source_Evolution!$N$3:$N$731,Source_Evolution!$D$3:$D$731,"Luxembourg") | L14: =SUMIFS(Source_Evolution!$O$3:$O$731,Source_Evolution!$D$3:$D$731,"Luxembourg") | M14: =SUMIFS(Source_Evolution!$P$3:$P$731,Source_Evolution!$D$3:$D$731,"Luxembourg") | N14: =SUMIFS(Source_Evolution!$Q$3:$Q$731,Source_Evolution!$D$3:$D$731,"Luxembourg") | O14: =IFERROR((N14/B14)^(1/12)-1,"-") | P14: =IFERROR(N14/N$28,"-")
